<?xml version="1.0" ?>
<!-- =================================================================================== -->
<!-- |    This document was autogenerated by xacro from myrobot.urdf.xacro             | -->
<!-- |    EDITING THIS FILE BY HAND IS NOT RECOMMENDED                                 | -->
<!-- =================================================================================== -->
<robot name="myrobot">
  <material name="silver">
    <color rgba="0.700 0.700 0.700 1.000"/>
  </material>
  <transmission name="m1_tran">
    <type>transmission_interface/SimpleTransmission</type>
    <joint name="m1">
      <hardwareInterface>hardware_interface/EffortJointInterface</hardwareInterface>
    </joint>
    <actuator name="m1_actr">
      <hardwareInterface>hardware_interface/EffortJointInterface</hardwareInterface>
      <mechanicalReduction>1</mechanicalReduction>
    </actuator>
  </transmission>
  <transmission name="m2_tran">
    <type>transmission_interface/SimpleTransmission</type>
    <joint name="m2">
      <hardwareInterface>hardware_interface/EffortJointInterface</hardwareInterface>
    </joint>
    <actuator name="m2_actr">
      <hardwareInterface>hardware_interface/EffortJointInterface</hardwareInterface>
      <mechanicalReduction>1</mechanicalReduction>
    </actuator>
  </transmission>
  <transmission name="m3_tran">
    <type>transmission_interface/SimpleTransmission</type>
    <joint name="m3">
      <hardwareInterface>hardware_interface/EffortJointInterface</hardwareInterface>
    </joint>
    <actuator name="m3_actr">
      <hardwareInterface>hardware_interface/EffortJointInterface</hardwareInterface>
      <mechanicalReduction>1</mechanicalReduction>
    </actuator>
  </transmission>
  <transmission name="m4_tran">
    <type>transmission_interface/SimpleTransmission</type>
    <joint name="m4">
      <hardwareInterface>hardware_interface/EffortJointInterface</hardwareInterface>
    </joint>
    <actuator name="m4_actr">
      <hardwareInterface>hardware_interface/EffortJointInterface</hardwareInterface>
      <mechanicalReduction>1</mechanicalReduction>
    </actuator>
  </transmission>
  <gazebo>
    <plugin filename="libgazebo_ros_control.so" name="control"/>
  </gazebo>
  <gazebo reference="base_link">
    <material>Gazebo/Silver</material>
    <mu1>0.2</mu1>
    <mu2>0.2</mu2>
    <self_collide>true</self_collide>
    <gravity>true</gravity>
  </gazebo>
  <gazebo reference="link_1_1">
    <material>Gazebo/Silver</material>
    <mu1>0.2</mu1>
    <mu2>0.2</mu2>
    <self_collide>true</self_collide>
  </gazebo>
  <gazebo reference="link_2_1">
    <material>Gazebo/Silver</material>
    <mu1>0.2</mu1>
    <mu2>0.2</mu2>
    <self_collide>true</self_collide>
  </gazebo>
  <gazebo reference="link_3_1">
    <material>Gazebo/Silver</material>
    <mu1>0.2</mu1>
    <mu2>0.2</mu2>
    <self_collide>true</self_collide>
  </gazebo>
  <gazebo reference="link_4_1">
    <material>Gazebo/Silver</material>
    <mu1>0.2</mu1>
    <mu2>0.2</mu2>
    <self_collide>true</self_collide>
  </gazebo>
  <link name="base_link">
    <inertial>
      <origin rpy="0 0 0" xyz="-2.392851857687137e-05 -5.300803319461504e-09 0.00763304236283115"/>
      <mass value="2.933546779210685"/>
      <inertia ixx="0.004747" ixy="0.0" ixz="0.0" iyy="0.004749" iyz="-0.0" izz="0.00893"/>
    </inertial>
    <visual>
      <origin rpy="0 0 0" xyz="0 0 0"/>
      <geometry>
        <mesh filename="file:///home/jose/robotis_ws/install/myrobot_description/share/myrobot_description/meshes/base_link.stl" scale="0.001 0.001 0.001"/>
      </geometry>
      <material name="silver"/>
    </visual>
    <collision>
      <origin rpy="0 0 0" xyz="0 0 0"/>
      <geometry>
        <mesh filename="file:///home/jose/robotis_ws/install/myrobot_description/share/myrobot_description/meshes/base_link.stl" scale="0.001 0.001 0.001"/>
      </geometry>
    </collision>
  </link>
  <link name="link_1_1">
    <inertial>
      <origin rpy="0 0 0" xyz="-4.151294663686638e-07 -0.009279808040763556 0.10204796066778993"/>
      <mass value="0.9302052276738703"/>
      <inertia ixx="0.006061" ixy="-0.0" ixz="-0.0" iyy="0.006125" iyz="0.00042" izz="0.000787"/>
    </inertial>
    <visual>
      <origin rpy="0 0 0" xyz="-0.0 -0.0 -0.0312"/>
      <geometry>
        <mesh filename="file:///home/jose/robotis_ws/install/myrobot_description/share/myrobot_description/meshes/link_1_1.stl" scale="0.001 0.001 0.001"/>
      </geometry>
      <material name="silver"/>
    </visual>
    <collision>
      <origin rpy="0 0 0" xyz="-0.0 -0.0 -0.0312"/>
      <geometry>
        <mesh filename="file:///home/jose/robotis_ws/install/myrobot_description/share/myrobot_description/meshes/link_1_1.stl" scale="0.001 0.001 0.001"/>
      </geometry>
    </collision>
  </link>
  <link name="link_2_1">
    <inertial>
      <origin rpy="0 0 0" xyz="0.00036780303540046125 0.03076727172249008 0.012540618975346363"/>
      <mass value="1.6352826545494268"/>
      <inertia ixx="0.01147" ixy="7e-06" ixz="-2.2e-05" iyy="0.011884" iyz="-9.2e-05" izz="0.001574"/>
    </inertial>
    <visual>
      <origin rpy="0 0 0" xyz="-0.0 -0.002 -0.2182"/>
      <geometry>
        <mesh filename="file:///home/jose/robotis_ws/install/myrobot_description/share/myrobot_description/meshes/link_2_1.stl" scale="0.001 0.001 0.001"/>
      </geometry>
      <material name="silver"/>
    </visual>
    <collision>
      <origin rpy="0 0 0" xyz="-0.0 -0.002 -0.2182"/>
      <geometry>
        <mesh filename="file:///home/jose/robotis_ws/install/myrobot_description/share/myrobot_description/meshes/link_2_1.stl" scale="0.001 0.001 0.001"/>
      </geometry>
    </collision>
  </link>
  <link name="link_3_1">
    <inertial>
      <origin rpy="0 0 0" xyz="1.7277946714556383e-06 0.011962598890476739 0.04120294009153791"/>
      <mass value="0.43344163926540746"/>
      <inertia ixx="0.001762" ixy="-0.0" ixz="-0.0" iyy="0.001844" iyz="-4.8e-05" izz="0.000118"/>
    </inertial>
    <visual>
      <origin rpy="0 0 0" xyz="-0.0 -0.06063 -0.3682"/>
      <geometry>
        <mesh filename="file:///home/jose/robotis_ws/install/myrobot_description/share/myrobot_description/meshes/link_3_1.stl" scale="0.001 0.001 0.001"/>
      </geometry>
      <material name="silver"/>
    </visual>
    <collision>
      <origin rpy="0 0 0" xyz="-0.0 -0.06063 -0.3682"/>
      <geometry>
        <mesh filename="file:///home/jose/robotis_ws/install/myrobot_description/share/myrobot_description/meshes/link_3_1.stl" scale="0.001 0.001 0.001"/>
      </geometry>
    </collision>
  </link>
  <link name="link_4_1">
    <inertial>
      <origin rpy="0 0 0" xyz="-4.592120418693256e-08 0.003013178400541147 0.046242828124350266"/>
      <mass value="0.30089103090381814"/>
      <inertia ixx="0.000298" ixy="0.0" ixz="-0.0" iyy="0.000291" iyz="3.3e-05" izz="6.2e-05"/>
    </inertial>
    <visual>
      <origin rpy="0 0 0" xyz="0.0 -0.08208 -0.4882"/>
      <geometry>
        <mesh filename="file:///home/jose/robotis_ws/install/myrobot_description/share/myrobot_description/meshes/link_4_1.stl" scale="0.001 0.001 0.001"/>
      </geometry>
      <material name="silver"/>
    </visual>
    <collision>
      <origin rpy="0 0 0" xyz="0.0 -0.08208 -0.4882"/>
      <geometry>
        <mesh filename="file:///home/jose/robotis_ws/install/myrobot_description/share/myrobot_description/meshes/link_4_1.stl" scale="0.001 0.001 0.001"/>
      </geometry>
    </collision>
  </link>
  <joint name="m1" type="revolute">
    <origin rpy="0 0 0" xyz="0.0 0.0 0.0312"/>
    <parent link="base_link"/>
    <child link="link_1_1"/>
    <axis xyz="0.0 0.0 1.0"/>
    <limit upper="2.792527" lower="-2.792527" effort="100" velocity="100"/>
  </joint>
  <joint name="m2" type="revolute">
    <origin rpy="0 0 0" xyz="0.0 0.002 0.187"/>
    <parent link="link_1_1"/>
    <child link="link_2_1"/>
    <axis xyz="0.0 1.0 0.0"/>
    <limit effort="100" lower="-2.792527" upper="2.792527" velocity="100"/>
  </joint>
  <joint name="m3" type="revolute">
    <origin rpy="0 0 0" xyz="0.0 0.05863 0.15"/>
    <parent link="link_2_1"/>
    <child link="link_3_1"/>
    <axis xyz="0.0 1.0 -0.0"/>
    <limit effort="100" lower="-2.792527" upper="2.792527" velocity="100"/>
  </joint>
  <joint name="m4" type="revolute">
    <origin rpy="0 0 0" xyz="-0.0 0.02145 0.12"/>
    <parent link="link_3_1"/>
    <child link="link_4_1"/>
    <axis xyz="0.0 1.0 -0.0"/>
    <limit effort="100" lower="-2.792527" upper="2.792527" velocity="100"/>
  </joint>
  <ros2_control name="myrobot_ros2_control" type="system">
    <hardware>
      <plugin>dynamixel_hardware/DynamixelHardware</plugin>
      <param name="usb_port">/dev/ttyUSB0</param>
      <param name="baud_rate">115200</param>
      <!--<param name="use_dummy">true</param>-->
    </hardware>
    <joint name="m1">
      <param name="id">1</param>
      <command_interface initial_value="0.0" name="position"/>
      <!--command_interface name="velocity"/-->
      <state_interface name="position"/>
      <state_interface name="velocity"/>
      <!--state_interface name="effort"/-->
    </joint>
    <joint name="m2">
      <param name="id">2</param>
      <command_interface initial_value="0.0" name="position"/>
      <!--command_interface name="velocity"/-->
      <state_interface name="position"/>
      <state_interface name="velocity"/>
      <!--state_interface name="effort"/-->
    </joint>
    <joint name="m3">
      <param name="id">3</param>
      <command_interface initial_value="0.0" name="position"/>
      <!--command_interface name="velocity"/-->
      <state_interface name="position"/>
      <state_interface name="velocity"/>
      <!--state_interface name="effort"/-->
    </joint>
    <joint name="m4">
      <param name="id">4</param>
      <command_interface initial_value="0.0" name="position"/>
      <!--command_interface name="velocity"/-->
      <state_interface name="position"/>
      <state_interface name="velocity"/>
      <!--state_interface name="effort"/-->
    </joint>
  </ros2_control>
</robot>
