<?xml version="1.0" ?>
<robot name="myrobot" xmlns:xacro="http://www.ros.org/wiki/xacro">

<xacro:include filename="$(find myrobot_description)/urdf/materials.xacro" />
<xacro:include filename="$(find myrobot_description)/urdf/myrobot.trans" />
<xacro:include filename="$(find myrobot_description)/urdf/myrobot.gazebo" />
<link name="base_link">
  <inertial>
    <origin xyz="-2.392851857687137e-05 -5.300803319461504e-09 0.00763304236283115" rpy="0 0 0"/>
    <mass value="2.933546779210685"/>
    <inertia ixx="0.004747" iyy="0.004749" izz="0.00893" ixy="0.0" iyz="-0.0" ixz="0.0"/>
  </inertial>
  <visual>
    <origin xyz="0 0 0" rpy="0 0 0"/>
    <geometry>
      <mesh filename="file://$(find myrobot_description)/meshes/base_link.stl" scale="0.001 0.001 0.001"/>
    </geometry>
    <material name="silver"/>
  </visual>
  <collision>
    <origin xyz="0 0 0" rpy="0 0 0"/>
    <geometry>
      <mesh filename="file://$(find myrobot_description)/meshes/base_link.stl" scale="0.001 0.001 0.001"/>
    </geometry>
  </collision>
</link>

<link name="link_1_1">
  <inertial>
    <origin xyz="-4.151294663686638e-07 -0.009279808040763556 0.10204796066778993" rpy="0 0 0"/>
    <mass value="0.9302052276738703"/>
    <inertia ixx="0.006061" iyy="0.006125" izz="0.000787" ixy="-0.0" iyz="0.00042" ixz="-0.0"/>
  </inertial>
  <visual>
    <origin xyz="-0.0 -0.0 -0.0312" rpy="0 0 0"/>
    <geometry>
      <mesh filename="file://$(find myrobot_description)/meshes/link_1_1.stl" scale="0.001 0.001 0.001"/>
    </geometry>
    <material name="silver"/>
  </visual>
  <collision>
    <origin xyz="-0.0 -0.0 -0.0312" rpy="0 0 0"/>
    <geometry>
      <mesh filename="file://$(find myrobot_description)/meshes/link_1_1.stl" scale="0.001 0.001 0.001"/>
    </geometry>
  </collision>
</link>

<link name="link_2_1">
  <inertial>
    <origin xyz="0.00036780303540046125 0.03076727172249008 0.012540618975346363" rpy="0 0 0"/>
    <mass value="1.6352826545494268"/>
    <inertia ixx="0.01147" iyy="0.011884" izz="0.001574" ixy="7e-06" iyz="-9.2e-05" ixz="-2.2e-05"/>
  </inertial>
  <visual>
    <origin xyz="-0.0 -0.002 -0.2182" rpy="0 0 0"/>
    <geometry>
      <mesh filename="file://$(find myrobot_description)/meshes/link_2_1.stl" scale="0.001 0.001 0.001"/>
    </geometry>
    <material name="silver"/>
  </visual>
  <collision>
    <origin xyz="-0.0 -0.002 -0.2182" rpy="0 0 0"/>
    <geometry>
      <mesh filename="file://$(find myrobot_description)/meshes/link_2_1.stl" scale="0.001 0.001 0.001"/>
    </geometry>
  </collision>
</link>

<link name="link_3_1">
  <inertial>
    <origin xyz="1.7277946714556383e-06 0.011962598890476739 0.04120294009153791" rpy="0 0 0"/>
    <mass value="0.43344163926540746"/>
    <inertia ixx="0.001762" iyy="0.001844" izz="0.000118" ixy="-0.0" iyz="-4.8e-05" ixz="-0.0"/>
  </inertial>
  <visual>
    <origin xyz="-0.0 -0.06063 -0.3682" rpy="0 0 0"/>
    <geometry>
      <mesh filename="file://$(find myrobot_description)/meshes/link_3_1.stl" scale="0.001 0.001 0.001"/>
    </geometry>
    <material name="silver"/>
  </visual>
  <collision>
    <origin xyz="-0.0 -0.06063 -0.3682" rpy="0 0 0"/>
    <geometry>
      <mesh filename="file://$(find myrobot_description)/meshes/link_3_1.stl" scale="0.001 0.001 0.001"/>
    </geometry>
  </collision>
</link>

<link name="link_4_1">
  <inertial>
    <origin xyz="-4.592120418693256e-08 0.003013178400541147 0.046242828124350266" rpy="0 0 0"/>
    <mass value="0.30089103090381814"/>
    <inertia ixx="0.000298" iyy="0.000291" izz="6.2e-05" ixy="0.0" iyz="3.3e-05" ixz="-0.0"/>
  </inertial>
  <visual>
    <origin xyz="0.0 -0.08208 -0.4882" rpy="0 0 0"/>
    <geometry>
      <mesh filename="file://$(find myrobot_description)/meshes/link_4_1.stl" scale="0.001 0.001 0.001"/>
    </geometry>
    <material name="silver"/>
  </visual>
  <collision>
    <origin xyz="0.0 -0.08208 -0.4882" rpy="0 0 0"/>
    <geometry>
      <mesh filename="file://$(find myrobot_description)/meshes/link_4_1.stl" scale="0.001 0.001 0.001"/>
    </geometry>
  </collision>
</link>

<joint name="l1_bl" type="revolute">
  <origin xyz="0.0 0.0 0.0312" rpy="0 0 0"/>
  <parent link="base_link"/>
  <child link="link_1_1"/>
  <axis xyz="0.0 0.0 -1.0"/>
  <limit upper="5.585054" lower="0.0" effort="100" velocity="100"/>
</joint>

<joint name="l2_l1" type="revolute">
  <origin xyz="0.0 0.002 0.187" rpy="0 0 0"/>
  <parent link="link_1_1"/>
  <child link="link_2_1"/>
  <axis xyz="0.0 1.0 0.0"/>
  <limit upper="2.792527" lower="-2.792527" effort="100" velocity="100"/>
</joint>

<joint name="l3_l2" type="revolute">
  <origin xyz="0.0 0.05863 0.15" rpy="0 0 0"/>
  <parent link="link_2_1"/>
  <child link="link_3_1"/>
  <axis xyz="0.0 1.0 -0.0"/>
  <limit upper="2.792527" lower="-2.792527" effort="100" velocity="100"/>
</joint>

<joint name="l4_l3" type="revolute">
  <origin xyz="-0.0 0.02145 0.12" rpy="0 0 0"/>
  <parent link="link_3_1"/>
  <child link="link_4_1"/>
  <axis xyz="0.0 1.0 -0.0"/>
  <limit upper="2.792527" lower="-2.792527" effort="100" velocity="100"/>
</joint>

</robot>
